package reactor.assertj.util.function;

import org.junit.jupiter.api.Test;

import reactor.assertj.ReactorAssertions;
import reactor.util.function.Tuple4;
import reactor.util.function.Tuples;

import static org.assertj.core.api.Assertions.assertThatCode;
import static org.assertj.core.api.Assertions.assertThatExceptionOfType;

class Tuple4AssertTest {

	final Tuple4<String, Integer, Long, String>       testData  = Tuples.of("example", 123, 45L, "fourth");
	final Tuple4Assert<String, Integer, Long, String> assertion = ReactorAssertions.assertThat(testData);

	@Test
	void hasT1() {
		assertThatCode(() ->
				assertion.hasT1("example")
		).doesNotThrowAnyException();
	}

	@Test
	void hasT1Fails() {
		assertThatExceptionOfType(AssertionError.class).isThrownBy(() ->
				assertion.hasT1("examples")
		).withMessage("Expected Tuple4 to have first part <examples> but was <example>");
	}

	@Test
	void hasT2() {
		assertThatCode(() ->
				assertion.hasT2(123)
		).doesNotThrowAnyException();
	}

	@Test
	void hasT2Fails() {
		assertThatExceptionOfType(AssertionError.class).isThrownBy(() ->
				assertion.hasT2(1234)
		).withMessage("Expected Tuple4 to have second part <1234> but was <123>");
	}

	@Test
	void hasT3() {
		assertThatCode(() ->
				assertion.hasT3(45L)
		).doesNotThrowAnyException();
	}

	@Test
	void hasT3Fails() {
		assertThatExceptionOfType(AssertionError.class).isThrownBy(() ->
				assertion.hasT3(46L)
		).withMessage("Expected Tuple4 to have third part <46> but was <45>");
	}

	@Test
	void hasT4() {
		assertThatCode(() ->
				assertion.hasT4("fourth")
		).doesNotThrowAnyException();
	}

	@Test
	void hasT4Fails() {
		assertThatExceptionOfType(AssertionError.class).isThrownBy(() ->
				assertion.hasT4("foorth")
		).withMessage("Expected Tuple4 to have fourth part <foorth> but was <fourth>");
	}
}
